Workbook
Name ALTA_VERAPAZ: #REF!
Name ALTA_VERAPAZ: #REF!
Name ALTA_VERAPAZ: #REF!
Name BAJA_VERAPAZ: #REF!
Name BAJA_VERAPAZ: #REF!
Name BAJA_VERAPAZ: #REF!
Name CHIMALTENANGO: #REF!
Name CHIMALTENANGO: #REF!
Name CHIMALTENANGO: #REF!
Name CHIQUIMULA: #REF!
Name CHIQUIMULA: #REF!
Name CHIQUIMULA: #REF!
Name CIUDAD_PORTUARIA: #REF!
Name CIUDAD_PORTUARIA: #REF!
Name CIUDAD_PORTUARIA: #REF!
Name CIUDAD_TURISTICA: #REF!
Name CIUDAD_TURISTICA: #REF!
Name CIUDAD_TURISTICA: #REF!
Name CORREDOR: #REF!
Name CORREDOR: #REF!
Name CORREDOR: #REF!
Name DEPTO00: 'ICL 2023 (12 pilares)'!$D$10:$D$385
Name DEPTO00: 'ICL 2024 (12 pilares)'!$D$10:$D$385
Name DEPTO00: 'ICL 2024 (datos serie original)'!$D$10:$D$385
Name DEPTO00: 'ICL 2024 (Indicadores base 100)'!$D$10:$D$385
Name DEPTO00: 'ICL 2024 (Resumen)'!$D$10:$D$385
Name DEPTO01: #REF!
Name DEPTO01: #REF!
Name DEPTO01: #REF!
Name DEPTO02: #REF!
Name DEPTO02: #REF!
Name DEPTO02: #REF!
Name DEPTO03: #REF!
Name DEPTO03: #REF!
Name DEPTO03: #REF!
Name DEPTO04: #REF!
Name DEPTO04: #REF!
Name DEPTO04: #REF!
Name DEPTO05: #REF!
Name DEPTO05: #REF!
Name DEPTO05: #REF!
Name DEPTO06: #REF!
Name DEPTO06: #REF!
Name DEPTO06: #REF!
Name DEPTO07: #REF!
Name DEPTO07: #REF!
Name DEPTO07: #REF!
Name DEPTO08: #REF!
Name DEPTO08: #REF!
Name DEPTO08: #REF!
Name DEPTO09: #REF!
Name DEPTO09: #REF!
Name DEPTO09: #REF!
Name DEPTO10: #REF!
Name DEPTO10: #REF!
Name DEPTO10: #REF!
Name DEPTO11: #REF!
Name DEPTO11: #REF!
Name DEPTO11: #REF!
Name DEPTO12: #REF!

Sheet ICL 2024 (Resumen)
D2: ÍNDICE DE COMPETITIVIDAD LOCAL
D4: Fundación para el Desarrollo de Guatemala - FUNDESA -
D5: RESUMEN: variables sociodemográficas y económicas
D6: Datos Generales por Territorio
B9: NO. | C9: CÓDIGO DEPARTAMENTO | D9: DEPARTAMENTO | E9: CÓDIGO MUNICIPIO | F9: MUNICIPIO | G9: ICL 2024 | H9: RANKING (s/340) | I9: PIB per cápita 2023 (US$ al año) | J9: Población (2023) | K9: % No Ladinos (2018) | L9: Extensión Territorial (Km2) | M9: Urbanización (2018)
B10: 1 | C10: 1 | D10: GUATEMALA | E10: 101 | F10: Guatemala | G10: 79.015635 | H10: 1 | I10: 24741.856 | J10: 1221739 | K10: 0.0868 | L10: 184 | M10: 1
B11: 17 | C11: 1 | D11: GUATEMALA | E11: 117 | F11: San Miguel Petapa | G11: 73.881582 | H11: 2 | I11: 7589.0774 | J11: 152666 | K11: 0.0658 | L11: 30 | M11: 0.95333225
B12: 8 | C12: 1 | D12: GUATEMALA | E12: 108 | F12: Mixco | G12: 72.164621 | H12: 3 | I12: 12394.887 | J12: 527828 | K12: 0.1065 | L12: 132 | M12: 0.99412315
B13: 2 | C13: 1 | D13: GUATEMALA | E13: 102 | F13: Santa Catarina Pinula | G13: 72.003823 | H13: 4 | I13: 18727.882 | J13: 87717 | K13: 0.0549 | L13: 51 | M13: 0.88424284
B14: 26 | C14: 3 | D14: SACATEPEQUEZ | E14: 301 | F14: Antigua Guatemala | G14: 70.820475 | H14: 5 | I14: 9514.2496 | J14: 60608 | K14: 0.1273 | L14: 78 | M14: 1
B15: 13 | C15: 1 | D15: GUATEMALA | E15: 113 | F15: Fraijanes | G15: 70.801771 | H15: 6 | I15: 16475.126 | J15: 64519 | K15: 0.0692 | L15: 96 | M15: 0.75156791
B16: 15 | C16: 1 | D16: GUATEMALA | E16: 115 | F16: Villa Nueva | G16: 70.751706 | H16: 7 | I16: 11333.587 | J16: 492480 | K16: 0.059 | L16: 114 | M16: 0.98402329
B17: 33 | C17: 3 | D17: SACATEPEQUEZ | E17: 308 | F17: San Lucas Sacatepéquez | G17: 69.024305 | H17: 8 | I17: 12885.563 | J17: 29549 | K17: 0.1146 | L17: 5 | M17: 0.8858844
B18: 27 | C18: 3 | D18: SACATEPEQUEZ | E18: 302 | F18: Jocotenango | G18: 67.898638 | H18: 9 | I18: 4875.6138 | J18: 24144 | K18: 0.0837 | L18: 9 | M18: 0.8892391
B19: 16 | C19: 1 | D19: GUATEMALA | E19: 116 | F19: Villa Canales | G19: 67.712181 | H19: 10 | I19: 9203.2103 | J19: 168680 | K19: 0.0373 | L19: 160 | M19: 0.80523873
B20: 9 | C20: 1 | D20: GUATEMALA | E20: 109 | F20: San Pedro Sacatepéquez | G20: 67.079 | H20: 11 | I20: 9364.7475 | J20: 57362 | K20: 0.7653 | L20: 48 | M20: 0.72284181
B21: 3 | C21: 1 | D21: GUATEMALA | E21: 103 | F21: San José Pinula | G21: 67.050387 | H21: 12 | I21: 5706.5877 | J21: 90247 | K21: 0.0503 | L21: 220 | M21: 0.84641673
... B349: 234 | C349: 14 | D349: QUICHE | E349: 1405 | F349: Chajul | G349: 35.67105 | H349: 340 | I349: 1260.7837 | J349: 54355 | K349: 0.9156 | L349: 1524 | M349: 0.52343554
C351: 0 | D351: REPUBLICA | E351: 0 | G351: 56.501748 | I351: 6676.3278 | J351: 17602431 | K351: 0.4399 | L351: 108888.94 | M351: 0.5393545
C352: 1 | D352: GUATEMALA | E352: 100 | G352: 72.680385 | H352: 1 | I352: 14654.865 | J352: 3639725 | K352: 0.1449 | L352: 2126 | M352: 0.91286255
C353: 2 | D353: EL_PROGRESO | E353: 200 | G353: 55.222036 | H353: 5 | I353: 5502.5834 | J353: 196917 | K353: 0.0181 | L353: 1922 | M353: 0.52145903
C354: 3 | D354: SACATEPEQUEZ | E354: 300 | G354: 62.735935 | H354: 2 | I354: 6413.8096 | J354: 408476 | K354: 0.4096 | L354: 465 | M354: 0.88407387
C355: 4 | D355: CHIMALTENANGO | E355: 400 | G355: 49.971522 | H355: 14 | I355: 2841.711 | J355: 771887 | K355: 0.7862 | L355: 1979 | M355: 0.54332701
C356: 5 | D356: ESCUINTLA | E356: 500 | G356: 56.50077 | H356: 3 | I356: 10861.055 | J356: 823684 | K356: 0.0563 | L356: 4384 | M356: 0.61444991
C357: 6 | D357: SANTA_ROSA | E357: 600 | G357: 50.913855 | H357: 10 | I357: 4447.2812 | J357: 456928 | K357: 0.1676 | L357: 2955 | M357: 0.46716508
C358: 7 | D358: SOLOLA | E358: 700 | G358: 49.184076 | H358: 15 | I358: 3253.9791 | J358: 487906 | K358: 0.9667 | L358: 1061 | M358: 0.61772731
C359: 8 | D359: TOTONICAPAN | E359: 800 | G359: 44.66202 | H359: 19 | I359: 3705.3634 | J359: 507905 | K359: 0.982 | L359: 1061 | M359: 0.49062965
C360: 9 | D360: QUETZALTENANGO | E360: 900 | G360: 52.056907 | H360: 6 | I360: 7089.646 | J360: 936385 | K360: 0.5134 | L360: 1951 | M360: 0.61723814
C361: 10 | D361: SUCHITEPEQUEZ | E361: 1000 | G361: 50.225065 | H361: 13 | I361: 4277.2876 | J361: 626419 | K361: 0.3898 | L361: 2510 | M361: 0.48276779
C362: 11 | D362: RETALHULEU | E362: 1100 | G362: 50.541497 | H362: 12 | I362: 5334.3289 | J362: 386783 | K362: 0.1538 | L362: 1856 | M362: 0.57773431
C363: 12 | D363: SAN_MARCOS | E363: 1200 | G363: 46.318867 | H363: 17 | I363: 4681.3898 | J363: 1222951 | K363: 0.3104 | L363: 3791 | M363: 0.25614401
... C373: 22 | D373: JUTIAPA | E373: 2200 | G373: 51.951018 | H373: 7 | I373: 3875.9549 | J373: 563958 | K373: 0.209 | L373: 3219 | M373: 0.51543781
C375: 0 | D375: CIUDADES_INTERMEDIAS | G375: 63.27797 | I375: 11703.733 | J375: 6274407 | K375: 0.22691472 | L375: 20745 | M375: 0.80491224
C376: 1 | D376: NODO_REGIONAL | F376: AREA_METROPOLITANA | G376: 74.130042 | H376: 1 | I376: 16445.574 | J376: 2995219 | K376: 0.082218621 | L376: 1051 | M376: 0.96281288
C377: 2 | D377: CIUDAD_TURISTICA | F377: ANTIGUA_GUATEMALA | G377: 63.292104 | H377: 2 | I377: 5479.6404 | J377: 238138 | K377: 0.29259781 | L377: 369 | M377: 0.9383388
C378: 3 | D378: CIUDAD_PORTUARIA | F378: PUERTO_SAN_JOSE | G378: 56.660045 | H378: 5 | I378: 12681.478 | J378: 495196 | K378: 0.038008216 | L378: 2195 | M378: 0.64882954
C379: 4 | D379: NODO_REGIONAL | F379: LOS_ALTOS | G379: 58.342997 | H379: 3 | I379: 8711.4755 | J379: 475393 | K379: 0.6508448 | L379: 348 | M379: 0.81895003
C380: 5 | D380: NODO_REGIONAL | F380: GUATEMAGICA | G380: 51.512563 | H380: 8 | I380: 6423.4079 | J380: 493006 | K380: 0.11853179 | L380: 2264 | M380: 0.63699753
C381: 6 | D381: NODO_REGIONAL | F381: HUEHUETENANGO | G381: 49.136108 | H381: 9 | I381: 3959.905 | J381: 235078 | K381: 0.08615947 | L381: 697 | M381: 0.63049546
C382: 7 | D382: NODO_REGIONAL | F382: VERAPACES | G382: 42.006502 | H382: 10 | I382: 4483.3962 | J382: 689668 | K382: 0.91423686 | L382: 3534 | M382: 0.4464802
...

Sheet ICL 2024 (12 pilares)
D2: ÍNDICE DE COMPETITIVIDAD LOCAL
D4: Fundación para el Desarrollo de Guatemala - FUNDESA -
D5: PILARES 1 a 12: Resumen e Integración
D6: (valores en escala de 0 -negativo- a 100 -positivo-)
H7: 1 | I7: 2 | J7: 3 | K7: 4 | L7: 5 | M7: 6 | N7: 7 | O7: 8 | P7: 9 | Q7: 10 | R7: 11 | S7: 12
B9: NO. | C9: CÓDIGO DEPARTAMENTO | D9: DEPARTAMENTO | E9: CÓDIGO MUNICIPIO | F9: MUNICIPIO | G9: ICL 2024 | H9: INSTITUCIONES | I9: INFRAESTRUCTURA | J9: ADOPCIÓN DE TICs | K9: ENTORNO ECONÓMICO | L9: SALUD | M9: FUERZA LABORAL Y TALENTO | N9: INVERSIÓN PRODUCTIVA | O9: MERCADO LABORAL | P9: SISTEMA FINANCIERO | Q9: TAMAÑO DEL MERCADO | R9: DINAMISMO DE LOS NEGOCIOS | S9: CAPACIDAD DE INNOVACIÓN
B10: 1 | C10: 1 | D10: GUATEMALA | E10: 101 | F10: Guatemala | G10: 79.015635 | H10: 63.020156 | I10: 83.406544 | J10: 91.937435 | K10: 71.965838 | L10: 100 | M10: 71.109202 | N10: 47.485444 | O10: 88.723663 | P10: 81.77624 | Q10: 71.785304 | R10: 97.962154 | S10: 100
B11: 2 | C11: 1 | D11: GUATEMALA | E11: 102 | F11: Santa Catarina Pinula | G11: 72.003823 | H11: 55.210101 | I11: 80.621535 | J11: 97.018252 | K11: 73.388915 | L11: 51.193315 | M11: 51.500824 | N11: 97.131292 | O11: 83.083501 | P11: 85.959279 | Q11: 44.984588 | R11: 71.950454 | S11: 0
B12: 3 | C12: 1 | D12: GUATEMALA | E12: 103 | F12: San José Pinula | G12: 67.050387 | H12: 51.832904 | I12: 81.194054 | J12: 72.630748 | K12: 72.580986 | L12: 51.407344 | M12: 54.686963 | N12: 81.543345 | O12: 78.747203 | P12: 100 | Q12: 29.277801 | R12: 63.652905 | S12: 0
B13: 4 | C13: 1 | D13: GUATEMALA | E13: 104 | F13: San José Del Golfo | G13: 66.261395 | H13: 59.83803 | I13: 81.750942 | J13: 57.398469 | K13: 69.83963 | L13: 58.835302 | M13: 59.108929 | N13: 100 | O13: 74.585141 | P13: 100 | Q13: 5.2376046 | R13: 62.281303 | S13: 0
B14: 5 | C14: 1 | D14: GUATEMALA | E14: 105 | F14: Palencia | G14: 60.606081 | H14: 57.801265 | I14: 75.894171 | J14: 31.289931 | K14: 61.232854 | L14: 52.308548 | M14: 47.654074 | N14: 97.462168 | O14: 75.283632 | P14: 100 | Q14: 5.5867893 | R14: 62.153452 | S14: 0
B15: 6 | C15: 1 | D15: GUATEMALA | E15: 106 | F15: Chinautla | G15: 66.667577 | H15: 56.746811 | I15: 78.206332 | J15: 69.743507 | K15: 72.914556 | L15: 51.777239 | M15: 48.563217 | N15: 85.616338 | O15: 74.751047 | P15: 100 | Q15: 39.038639 | R15: 55.985659 | S15: 0
B16: 7 | C16: 1 | D16: GUATEMALA | E16: 107 | F16: San Pedro Ayampuc | G16: 61.609089 | H16: 48.620826 | I16: 66.758686 | J16: 58.620379 | K16: 68.849843 | L16: 51.55114 | M16: 41.603123 | N16: 92.25494 | O16: 73.504828 | P16: 100 | Q16: 19.186183 | R16: 56.750037 | S16: 0
B17: 8 | C17: 1 | D17: GUATEMALA | E17: 108 | F17: Mixco | G17: 72.164621 | H17: 61.154067 | I17: 82.932825 | J17: 95.643939 | K17: 71.01712 | L17: 51.072555 | M17: 60.235636 | N17: 72.97318 | O17: 83.948307 | P17: 94.752121 | Q17: 48.505846 | R17: 71.575235 | S17: 0
B18: 9 | C18: 1 | D18: GUATEMALA | E18: 109 | F18: San Pedro Sacatepéquez | G18: 67.079 | H18: 70.323934 | I18: 77.509198 | J18: 76.412956 | K18: 66.506876 | L18: 46.634857 | M18: 40.16841 | N18: 91.914048 | O18: 74.203015 | P18: 100 | Q18: 30.96274 | R18: 63.232968 | S18: 0
B19: 10 | C19: 1 | D19: GUATEMALA | E19: 110 | F19: San Juan Sacatepéquez | G19: 60.982244 | H19: 74.055659 | I19: 71.959931 | J19: 40.215115 | K19: 61.478463 | L19: 39.984394 | M19: 43.771895 | N19: 76.094304 | O19: 74.091187 | P19: 100 | Q19: 28.254686 | R19: 60.899048 | S19: 0
B20: 11 | C20: 1 | D20: GUATEMALA | E20: 111 | F20: San Raymundo | G20: 62.474739 | H20: 74.71297 | I20: 75.566307 | J20: 30.08153 | K20: 57.498619 | L20: 50.223132 | M20: 53.684327 | N20: 97.266907 | O20: 73.74363 | P20: 100 | Q20: 12.539634 | R20: 61.905076 | S20: 0
B21: 12 | C21: 1 | D21: GUATEMALA | E21: 112 | F21: Chuarrancho | G21: 59.648101 | H21: 70.139924 | I21: 74.434343 | J21: 18.230262 | K21: 62.376707 | L21: 50.806709 | M21: 34.736423 | N21: 100 | O21: 73.835674 | P21: 100 | Q21: 11.780576 | R21: 59.788494 | S21: 0
... B349: 340 | C349: 22 | D349: JUTIAPA | E349: 2217 | F349: Quesada | G349: 55.412217 | H349: 70.555221 | I349: 73.175578 | J349: 40.618631 | K349: 50.86352 | L349: 53.19485 | M349: 49.011415 | N349: 50.797283 | O349: 58.589623 | P349: 84.650891 | Q349: 23.598206 | R349: 54.479169 | S349: 0
C351: 0 | D351: REPUBLICA | E351: 0 | G351: 56.501748 | H351: 55.712844 | I351: 72.677546 | J351: 25.35294 | K351: 59.342055 | L351: 50.33246 | M351: 48.680911 | N351: 50.532556 | O351: 69.867749 | P351: 89.969114 | Q351: 31.663287 | R351: 67.387768 | S351: 0
C352: 1 | D352: GUATEMALA | E352: 100 | G352: 72.680385 | H352: 59.234972 | I352: 80.874823 | J352: 89.548043 | K352: 73.230795 | L352: 75.867125 | M352: 60.699556 | N352: 57.362597 | O352: 89.204357 | P352: 90.742243 | Q352: 43.539432 | R352: 79.180297 | S352: 81.053887
C353: 2 | D353: EL_PROGRESO | E353: 200 | G353: 55.222036 | H353: 62.857283 | I353: 73.943895 | J353: 25.945493 | K353: 64.399435 | L353: 58.304458 | M353: 51.154282 | N353: 44.705866 | O353: 69.673362 | P353: 62.079096 | Q353: 31.297193 | R353: 63.082028 | S353: 0
C354: 3 | D354: SACATEPEQUEZ | E354: 300 | G354: 62.735935 | H354: 51.181049 | I354: 81.369362 | J354: 56.231272 | K354: 76.112058 | L354: 51.657344 | M354: 49.406051 | N354: 44.215444 | O354: 77.507394 | P354: 69.075865 | Q354: 67.806218 | R354: 65.533232 | S354: 0
C355: 4 | D355: CHIMALTENANGO | E355: 400 | G355: 49.971522 | H355: 56.024252 | I355: 73.514673 | J355: 24.626034 | K355: 72.162278 | L355: 39.498819 | M355: 43.043772 | N355: 42.780189 | O355: 56.592018 | P355: 79.632786 | Q355: 7.3885738 | R355: 54.423345 | S355: 0
C356: 5 | D356: ESCUINTLA | E356: 500 | G356: 56.50077 | H356: 42.796039 | I356: 69.124143 | J356: 26.21342 | K356: 76.555782 | L356: 57.957072 | M356: 59.129836 | N356: 40.836248 | O356: 88.793012 | P356: 52.477416 | Q356: 37.40745 | R356: 70.218055 | S356: 0
C357: 6 | D357: SANTA_ROSA | E357: 600 | G357: 50.913855 | H357: 63.35852 | I357: 68.495322 | J357: 26.450532 | K357: 49.724896 | L357: 63.145352 | M357: 42.724099 | N357: 31.835789 | O357: 57.83469 | P357: 66.855818 | Q357: 29.515233 | R357: 60.112158 | S357: 0
C358: 7 | D358: SOLOLA | E358: 700 | G358: 49.184076 | H358: 67.044948 | I358: 69.510127 | J358: 24.172315 | K358: 59.810109 | L358: 36.11885 | M358: 45.573851 | N358: 42.290247 | O358: 46.666328 | P358: 74.347601 | Q358: 18.60115 | R358: 56.88931 | S358: 0
C359: 8 | D359: TOTONICAPAN | E359: 800 | G359: 44.66202 | H359: 76.575837 | I359: 56.514775 | J359: 20.954942 | K359: 60.050949 | L359: 29.977595 | M359: 37.174307 | N359: 31.937782 | O359: 40.74521 | P359: 60.834415 | Q359: 19.256203 | R359: 57.260208 | S359: 0
C360: 9 | D360: QUETZALTENANGO | E360: 900 | G360: 52.056907 | H360: 53.083693 | I360: 60.717072 | J360: 37.366973 | K360: 68.946763 | L360: 49.193517 | M360: 49.724693 | N360: 32.5912 | O360: 61.004402 | P360: 67.547538 | Q360: 25.899638 | R360: 66.550493 | S360: 0
C361: 10 | D361: SUCHITEPEQUEZ | E361: 1000 | G361: 50.225065 | H361: 62.698016 | I361: 58.093536 | J361: 25.517268 | K361: 64.721127 | L361: 48.119495 | M361: 45.183408 | N361: 34.270365 | O361: 66.367503 | P361: 65.2957 | Q361: 21.686662 | R361: 60.522639 | S361: 0
C362: 11 | D362: RETALHULEU | E362: 1100 | G362: 50.541497 | H362: 56.713171 | I362: 48.54767 | J362: 26.264584 | K362: 66.487842 | L362: 54.227296 | M362: 54.967365 | N362: 32.697774 | O362: 65.884417 | P362: 63.919746 | Q362: 21.267424 | R362: 64.979175 | S362: 0
... C373: 22 | D373: JUTIAPA | E373: 2200 | G373: 51.951018 | H373: 67.359171 | I373: 70.442039 | J373: 26.47917 | K373: 49.400741 | L373: 56.20159 | M373: 44.696516 | N373: 32.911694 | O373: 60.351822 | P373: 80.042821 | Q373: 24.833667 | R373: 58.741962 | S373: 0
C375: 0 | D375: CIUDADES_INTERMEDIAS | G375: 63.27797 | H375: 47.796467 | I375: 69.040129 | J375: 42.57307 | K375: 69.967288 | L375: 69.460911 | M375: 57.941942 | N375: 55.990631 | O375: 81.08552 | P375: 87.577059 | Q375: 38.788213 | R375: 75.836438 | S375: 65.945949
C376: 1 | D376: NODO_REGIONAL | F376: AREA_METROPOLITANA | G376: 74.130042 | H376: 60.732009 | I376: 80.84134 | J376: 93.11648 | K376: 72.949693 | L376: 81.10166 | M376: 62.344458 | N376: 56.696373 | O376: 89.257435 | P376: 88.347574 | Q376: 47.95885 | R376: 82.084587 | S376: 91.337961
C377: 2 | D377: CIUDAD_TURISTICA | F377: ANTIGUA_GUATEMALA | G377: 63.292104 | H377: 49.39039 | I377: 81.272794 | J377: 48.744616 | K377: 76.516457 | L377: 59.979624 | M377: 51.457753 | N377: 45.586032 | O377: 77.847692 | P377: 73.393419 | Q377: 67.380518 | R377: 64.643848 | S377: 0
C378: 3 | D378: CIUDAD_PORTUARIA | F378: PUERTO_SAN_JOSE | G378: 56.660045 | H378: 42.524199 | I378: 67.81123 | J378: 28.684344 | K378: 77.177498 | L378: 60.497069 | M378: 60.857517 | N378: 37.535926 | O378: 88.834418 | P378: 51.225632 | Q378: 37.573918 | R378: 70.538745 | S378: 0
C379: 4 | D379: NODO_REGIONAL | F379: LOS_ALTOS | G379: 58.342997 | H379: 58.287442 | I379: 66.110036 | J379: 72.831074 | K379: 77.012105 | L379: 57.309822 | M379: 54.014559 | N379: 28.861154 | O379: 61.956578 | P379: 62.191823 | Q379: 34.14898 | R379: 69.049396 | S379: 0
C380: 5 | D380: NODO_REGIONAL | F380: GUATEMAGICA | G380: 51.512563 | H380: 47.108486 | I380: 51.432394 | J380: 30.281418 | K380: 69.523799 | L380: 66.518538 | M380: 57.529563 | N380: 30.670546 | O380: 66.177294 | P380: 62.348936 | Q380: 17.771391 | R380: 67.275826 | S380: 0
C381: 6 | D381: NODO_REGIONAL | F381: HUEHUETENANGO | G381: 49.136108 | H381: 67.131903 | I381: 58.810776 | J381: 32.323615 | K381: 60.058556 | L381: 61.653564 | M381: 47.453932 | N381: 16.676706 | O381: 50.729546 | P381: 60.118366 | Q381: 21.480707 | R381: 64.059523 | S381: 0
C382: 7 | D382: NODO_REGIONAL | F382: VERAPACES | G382: 42.006502 | H382: 62.948998 | I382: 56.129971 | J382: 15.457149 | K382: 36.619092 | L382: 44.692018 | M382: 35.604817 | N382: 21.51754 | O382: 56.20378 | P382: 39.254007 | Q382: 33.237789 | R382: 60.40636 | S382: 0
...

Sheet ICL 2023 (12 pilares)
D2: ÍNDICE DE COMPETITIVIDAD LOCAL
D4: Fundación para el Desarrollo de Guatemala - FUNDESA -
D5: PILARES 1 a 12: Resumen e Integración
D6: (valores en escala de 0 -negativo- a 100 -positivo-)
H7: 1 | I7: 2 | J7: 3 | K7: 4 | L7: 5 | M7: 6 | N7: 7 | O7: 8 | P7: 9 | Q7: 10 | R7: 11 | S7: 12
B9: NO. | C9: CÓDIGO DEPARTAMENTO | D9: DEPARTAMENTO | E9: CÓDIGO MUNICIPIO | F9: MUNICIPIO | G9: ICL 2023 | H9: INSTITUCIONES | I9: INFRAESTRUCTURA | J9: ADOPCIÓN DE TICs | K9: ENTORNO ECONÓMICO | L9: SALUD | M9: FUERZA LABORAL Y TALENTO | N9: INVERSIÓN PRODUCTIVA | O9: MERCADO LABORAL | P9: SISTEMA FINANCIERO | Q9: TAMAÑO DEL MERCADO | R9: DINAMISMO DE LOS NEGOCIOS | S9: CAPACIDAD DE INNOVACIÓN
B10: 1 | C10: 1 | D10: GUATEMALA | E10: 101 | F10: Guatemala | G10: 78.722893 | H10: 62.547426 | I10: 82.986585 | J10: 92.216914 | K10: 68.318666 | L10: 100 | M10: 66.164609 | N10: 48.952481 | O10: 91.249888 | P10: 83.121577 | Q10: 72.431525 | R10: 97.962154 | S10: 100
B11: 2 | C11: 1 | D11: GUATEMALA | E11: 102 | F11: Santa Catarina Pinula | G11: 72.028875 | H11: 52.48098 | I11: 80.20491 | J11: 97.209313 | K11: 70.123424 | L11: 51.375311 | M11: 50.603928 | N11: 99.902096 | O11: 84.996506 | P11: 87.879287 | Q11: 45.598861 | R11: 71.943004 | S11: 0
B12: 3 | C12: 1 | D12: GUATEMALA | E12: 103 | F12: San José Pinula | G12: 64.635782 | H12: 51.902802 | I12: 80.769095 | J12: 56.052809 | K12: 60.184574 | L12: 51.490185 | M12: 55.212991 | N12: 83.040003 | O12: 80.783042 | P12: 100 | Q12: 27.643814 | R12: 63.91429 | S12: 0
B13: 4 | C13: 1 | D13: GUATEMALA | E13: 104 | F13: San José Del Golfo | G13: 64.167365 | H13: 66.95834 | I13: 81.29765 | J13: 38.221381 | K13: 56.234802 | L13: 60.810807 | M13: 57.686887 | N13: 100 | O13: 76.438951 | P13: 100 | Q13: 5.8810638 | R13: 62.311137 | S13: 0
B14: 5 | C14: 1 | D14: GUATEMALA | E14: 105 | F14: Palencia | G14: 62.609445 | H14: 64.895078 | I14: 75.424213 | J14: 45.809196 | K14: 44.142128 | L14: 52.166712 | M14: 45.373608 | N14: 100 | O14: 78.076054 | P14: 100 | Q14: 20.412533 | R14: 62.404367 | S14: 0
B15: 6 | C15: 1 | D15: GUATEMALA | E15: 106 | F15: Chinautla | G15: 68.019652 | H15: 61.886297 | I15: 77.756373 | J15: 90.370683 | K15: 67.754945 | L15: 51.789021 | M15: 45.088958 | N15: 83.632251 | O15: 77.543702 | P15: 100 | Q15: 36.100864 | R15: 56.293081 | S15: 0
B16: 7 | C16: 1 | D16: GUATEMALA | E16: 107 | F16: San Pedro Ayampuc | G16: 58.802089 | H16: 35.149406 | I16: 66.288727 | J16: 55.909941 | K16: 52.319626 | L16: 51.413104 | M16: 37.820916 | N16: 100 | O16: 75.893676 | P16: 100 | Q16: 14.754705 | R16: 57.272877 | S16: 0
B17: 8 | C17: 1 | D17: GUATEMALA | E17: 108 | F17: Mixco | G17: 72.688283 | H17: 63.265744 | I17: 82.507866 | J17: 100 | K17: 67.115495 | L17: 51.435875 | M17: 59.295239 | N17: 72.197951 | O17: 85.799568 | P17: 97.186291 | Q17: 49.108799 | R17: 71.658286 | S17: 0
B18: 9 | C18: 1 | D18: GUATEMALA | E18: 109 | F18: San Pedro Sacatepéquez | G18: 65.514498 | H18: 71.263364 | I18: 77.092572 | J18: 76.794588 | K18: 47.816639 | L18: 47.438082 | M18: 36.783556 | N18: 88.321855 | O18: 76.865733 | P18: 100 | Q18: 34.932906 | R18: 63.350181 | S18: 0
B19: 10 | C19: 1 | D19: GUATEMALA | E19: 110 | F19: San Juan Sacatepéquez | G19: 60.614883 | H19: 72.584988 | I19: 71.529972 | J19: 53.851148 | K19: 41.854693 | L19: 40.260788 | M19: 41.458017 | N19: 73.774343 | O19: 76.943313 | P19: 100 | Q19: 33.433038 | R19: 61.073412 | S19: 0
B20: 11 | C20: 1 | D20: GUATEMALA | E20: 111 | F20: San Raymundo | G20: 60.544509 | H20: 74.011589 | I20: 75.149681 | J20: 38.039661 | K20: 39.034468 | L20: 50.609893 | M20: 52.801795 | N20: 93.250911 | O20: 75.023024 | P20: 100 | Q20: 6.2414028 | R20: 61.827174 | S20: 0
B21: 12 | C21: 1 | D21: GUATEMALA | E21: 112 | F21: Chuarrancho | G21: 58.503747 | H21: 70.130616 | I21: 73.86605 | J21: 22.697636 | K21: 43.861961 | L21: 52.963512 | M21: 36.893977 | N21: 100 | O21: 75.851072 | P21: 100 | Q21: 7.4084253 | R21: 59.867963 | S21: 0
... B349: 340 | C349: 22 | D349: JUTIAPA | E349: 2217 | F349: Quesada | G349: 56.580528 | H349: 72.600663 | I349: 73.104024 | J349: 48.907847 | K349: 51.370483 | L349: 53.075486 | M349: 47.595772 | N349: 50.265962 | O349: 61.687525 | P349: 84.127525 | Q349: 24.857176 | R349: 54.79335 | S349: 0
C351: 0 | D351: REPUBLICA | E351: 0 | G351: 56.69944 | H351: 55.321127 | I351: 72.25243 | J351: 28.495078 | K351: 53.978545 | L351: 52.258655 | M351: 47.050902 | N351: 50.030404 | O351: 72.670931 | P351: 91.710479 | Q351: 32.35818 | R351: 67.567104 | S351: 0
C352: 1 | D352: GUATEMALA | E352: 100 | G352: 73.078197 | H352: 59.180653 | I352: 80.424864 | J352: 89.992698 | K352: 69.922895 | L352: 80.173454 | M352: 58.255616 | N352: 57.627038 | O352: 91.964521 | P352: 92.902177 | Q352: 44.185967 | R352: 79.230288 | S352: 80.541269
C353: 2 | D353: EL_PROGRESO | E353: 200 | G353: 56.344762 | H353: 67.863921 | I353: 73.458154 | J353: 28.762571 | K353: 57.86645 | L353: 59.575197 | M353: 46.972708 | N353: 42.876932 | O353: 73.100959 | P353: 70.797932 | Q353: 35.151422 | R353: 63.366137 | S353: 0
C354: 3 | D354: SACATEPEQUEZ | E354: 300 | G354: 65.248254 | H354: 55.401862 | I354: 80.704794 | J354: 77.394329 | K354: 70.600991 | L354: 53.12482 | M354: 48.628133 | N354: 44.066814 | O354: 82.777193 | P354: 71.656883 | Q354: 67.799428 | R354: 65.575547 | S354: 0
C355: 4 | D355: CHIMALTENANGO | E355: 400 | G355: 49.038061 | H355: 58.611328 | I355: 73.383927 | J355: 29.57596 | K355: 56.935182 | L355: 40.574364 | M355: 41.846144 | N355: 39.226196 | O355: 57.592768 | P355: 79.992743 | Q355: 6.9413684 | R355: 54.738695 | S355: 0
C356: 5 | D356: ESCUINTLA | E356: 500 | G356: 55.923106 | H356: 49.083972 | I356: 69.029143 | J356: 30.880893 | K356: 66.353731 | L356: 60.225464 | M356: 54.575079 | N356: 32.943651 | O356: 94.028455 | P356: 52.443737 | Q356: 34.657384 | R356: 70.932656 | S356: 0
C357: 6 | D357: SANTA_ROSA | E357: 600 | G357: 51.623907 | H357: 60.789684 | I357: 68.453656 | J357: 30.096478 | K357: 54.414739 | L357: 63.903671 | M357: 41.25788 | N357: 30.379412 | O357: 59.594949 | P357: 69.276751 | Q357: 29.33755 | R357: 60.358212 | S357: 0
C358: 7 | D358: SOLOLA | E358: 700 | G358: 47.176688 | H358: 64.96971 | I358: 68.210669 | J358: 31.055063 | K358: 47.890767 | L358: 34.50082 | M358: 44.916871 | N358: 37.453443 | O358: 46.143097 | P358: 73.512431 | Q358: 13.231738 | R358: 57.058954 | S358: 0
C359: 8 | D359: TOTONICAPAN | E359: 800 | G359: 43.943548 | H359: 80.094933 | I359: 56.227577 | J359: 26.17664 | K359: 47.768074 | L359: 31.405093 | M359: 36.069881 | N359: 28.963296 | O359: 38.32965 | P359: 61.165989 | Q359: 19.643238 | R359: 57.53466 | S359: 0
C360: 9 | D360: QUETZALTENANGO | E360: 900 | G360: 51.411829 | H360: 51.013632 | I360: 60.378513 | J360: 46.452804 | K360: 54.612683 | L360: 51.369255 | M360: 49.132941 | N360: 28.804187 | O360: 61.218024 | P360: 69.422146 | Q360: 26.479318 | R360: 66.646616 | S360: 0
C361: 10 | D361: SUCHITEPEQUEZ | E361: 1000 | G361: 49.635219 | H361: 61.687299 | I361: 57.891138 | J361: 29.704836 | K361: 54.350586 | L361: 48.628025 | M361: 43.995013 | N361: 31.389639 | O361: 69.47728 | P361: 66.318997 | Q361: 21.675125 | R361: 60.869467 | S361: 0
C362: 11 | D362: RETALHULEU | E362: 1100 | G362: 50.624933 | H362: 57.296677 | I362: 48.455622 | J362: 30.577333 | K362: 58.569871 | L362: 55.213048 | M362: 53.005858 | N362: 33.732949 | O362: 67.775323 | P362: 64.382519 | Q362: 22.358954 | R362: 65.506112 | S362: 0
... C373: 22 | D373: JUTIAPA | E373: 2200 | G373: 53.154508 | H373: 69.732359 | I373: 70.230485 | J373: 30.434261 | K373: 48.485469 | L373: 57.821137 | M373: 42.478361 | N373: 31.685835 | O373: 63.499156 | P373: 80.922292 | Q373: 30.370947 | R373: 59.039283 | S373: 0
C375: 0 | D375: CIUDADES_INTERMEDIAS | G375: 63.957294 | H375: 48.183227 | I375: 68.582187 | J375: 50.965983 | K375: 62.200957 | L375: 73.108761 | M375: 55.850193 | N375: 55.542574 | O375: 84.514236 | P375: 89.518007 | Q375: 39.1444 | R375: 75.919703 | S375: 66.007263
C376: 1 | D376: NODO_REGIONAL | F376: AREA_METROPOLITANA | G376: 74.60102 | H376: 61.010118 | I376: 80.417493 | J376: 93.613448 | K376: 69.5664 | L376: 86.282958 | M376: 59.645502 | N376: 57.071492 | O376: 92.010817 | P376: 90.26208 | Q376: 48.607534 | R376: 82.123375 | S376: 91.689113
C377: 2 | D377: CIUDAD_TURISTICA | F377: ANTIGUA_GUATEMALA | G377: 65.524657 | H377: 54.761128 | I377: 80.589337 | J377: 65.285898 | K377: 70.716789 | L377: 62.283388 | M377: 50.930956 | N377: 44.715087 | O377: 82.975765 | P377: 76.408058 | Q377: 67.376448 | R377: 64.72837 | S377: 0
C378: 3 | D378: CIUDAD_PORTUARIA | F378: PUERTO_SAN_JOSE | G378: 56.58469 | H378: 50.058292 | I378: 67.717064 | J378: 34.72003 | K378: 66.707313 | L378: 63.361978 | M378: 56.347968 | N378: 32.111946 | O378: 94.173799 | P378: 51.201102 | Q378: 34.822143 | R378: 71.209954 | S378: 0
C379: 4 | D379: NODO_REGIONAL | F379: LOS_ALTOS | G379: 58.495752 | H379: 56.57667 | I379: 65.802289 | J379: 81.99772 | K379: 67.660136 | L379: 61.862801 | M379: 53.726606 | N379: 26.576343 | O379: 61.936361 | P379: 63.597676 | Q379: 34.648111 | R379: 69.068557 | S379: 0
C380: 5 | D380: NODO_REGIONAL | F380: GUATEMAGICA | G380: 51.474594 | H380: 52.02199 | I380: 51.259011 | J380: 35.369204 | K380: 60.068617 | L380: 65.989288 | M380: 55.928198 | N380: 29.811978 | O380: 67.076801 | P380: 63.311869 | Q380: 17.781012 | R380: 67.602565 | S380: 0
C381: 6 | D381: NODO_REGIONAL | F381: HUEHUETENANGO | G381: 48.822254 | H381: 61.267305 | I381: 58.778585 | J381: 35.903403 | K381: 57.936412 | L381: 64.994049 | M381: 48.756563 | N381: 13.896332 | O381: 49.571803 | P381: 50.654418 | Q381: 27.574191 | R381: 67.711731 | S381: 0
C382: 7 | D382: NODO_REGIONAL | F382: VERAPACES | G382: 41.81215 | H382: 59.535207 | I382: 55.683789 | J382: 17.045974 | K382: 35.777589 | L382: 46.261054 | M382: 34.048826 | N382: 20.19274 | O382: 58.263743 | P382: 39.008422 | Q382: 33.470858 | R382: 60.645455 | S382: 0
...

Sheet ICL 2024 (Indicadores base 100)
D2: ÍNDICE DE COMPETITIVIDAD LOCAL
D4: Fundación para el Desarrollo de Guatemala - FUNDESA -
D5: PILARES 1 a 12: Indicadores
D6: (valores en escala de 0 -negativo- a 100 -positivo-)
G8: 1.1 | H8: 1.2 | I8: 1.3 | J8: 1.4 | K8: 1.5 | L8: 1.6 | M8: 2.1 | N8: 2.2 | O8: 2.3 | P8: 2.4 | Q8: 2.5 | R8: 2.6 | S8: 3.1 | T8: 3.2 | U8: 4.1 | V8: 4.2 | W8: 4.3 | X8: 5.1 | Y8: 5.2 | Z8: 6.1 | AA8: 6.2 | AB8: 6.3 | AC8: 6.4 | AD8: 6.5 | AE8: 7.1 | AF8: 7.2 | AG8: 8.1 | AH8: 8.2 | AI8: 8.3 | AJ8: 8.4 | AK8: 8.5 | AL8: 8.6 | AM8: 9.1 | AN8: 9.2 | AO8: 9.3 | AP8: 9.4 | AQ8: 10.1 | AR8: 10.2 | AS8: 10.3 | AT8: 11.1 | AU8: 11.2 | AV8: 11.3 | AW8: 12.1
B9: NO. | C9: CÓDIGO DEPARTAMENTO | D9: DEPARTAMENTO | E9: CÓDIGO MUNICIPIO | F9: MUNICIPIO | G9: Tasa de Extorsiones | H9: Tasa de Homicidios | I9: Faltas Judiciales | J9: Conflictividad | K9: Gestión Municipal | L9: Información Catastral | M9: Brecha de la RED VIAL | N9: Distancia Promedio a Aeropuertos | O9: Distancia Promedio a Puertos | P9: Tasa de Electrificación | Q9: Cobertura de Agua y Saneamiento | R9: Déficit de Vivienda | S9: Radiobases de Telefonía Celular por Km2 | T9: Usuarios de Internet | U9: Tasa de Inflación | V9: Tasa de Pobreza | W9: Coeficiente de GINI | X9: Gasto Público en Salud, per cápita (al año) | Y9: Tasa de Desnutrición Crónica | Z9: Gasto Público en Educación, per cápita (al año) | AA9: Tasa Neta de Cobertura (todos niveles) | AB9: Alumnos por Docente (todos niveles) | AC9: Capacitación Técnica (% de la PEA) | AD9: % de LOGRO Graduandos (Mate y Lectura) | AE9: Carga Tributaria Local (% PIB) | AF9: Inversión Pública (% Presupuesto Local) | AG9: % de la PEA afiliada al IGSS | AH9: Afiliados por Patrono Particular | AI9: Peso del Gobierno en la contratación | AJ9: Salario Mínimo como No. veces Ingreso Medio | AK9: Ingreso Medio como % del Salario Formal | AL9: Tasa de Deportados | AM9: Km2 a cargo de cada Agencia | AN9: Agentes Bancarios por 100,000 hab. | AO9: Depósitos en relación al PIB per cápita | AP9: Cartera de Créditos en relación al PIB | AQ9: PIB local (US$ al año por Km2) | AR9: Remesas como % del PIB | AS9: Tasa de Turistas | AT9: Costo Iniciar un Negocio (% PIB per cápita) | AU9: Tiempo Iniciar un Negocio (días) | AV9: Fuerza Laboral Sector Servicios (% de la PEA) | AW9: Inversión I+D (% presupuesto local)
B10: 1 | C10: 1 | D10: GUATEMALA | E10: 101 | F10: Guatemala | G10: 0 | H10: 65.635712 | I10: 100 | J10: 50 | K10: 62.485224 | L10: 100 | M10: 53.26557 | N10: 95.663253 | O10: 74.679328 | P10: 99.99 | Q10: 95.448822 | R10: 81.392289 | S10: 100 | T10: 83.87487 | U10: 56.692385 | V10: 100 | W10: 59.205128 | X10: 100 | Y10: 100 | Z10: 89.931539 | AA10: 100 | AB10: 92.974353 | AC10: 52.304284 | AD10: 20.335834 | AE10: 84.971157 | AF10: 9.9997304 | AG10: 100 | AH10: 100 | AI10: 89.923551 | AJ10: 100 | AK10: 49.9512 | AL10: 92.467228 | AM10: 100 | AN10: 100 | AO10: 27.10496 | AP10: 100 | AQ10: 100 | AR10: 100 | AS10: 15.355912 | AT10: 100 | AU10: 93.886463 | AV10: 100 | AW10: 100
B11: 2 | C11: 1 | D11: GUATEMALA | E11: 102 | F11: Santa Catarina Pinula | G11: 0 | H11: 69.708059 | I11: 64.496556 | J11: 50 | K11: 47.055993 | L11: 100 | M11: 53.26557 | N11: 93.801147 | O11: 73.669719 | P11: 100 | Q11: 82.493521 | R11: 80.499253 | S11: 100 | T11: 94.036504 | U11: 56.692385 | V11: 100 | W11: 63.474359 | X11: 2.3866293 | Y11: 100 | Z11: 21.786235 | AA11: 100 | AB11: 53.007626 | AC11: 52.939813 | AD11: 29.770445 | AE11: 100 | AF11: 94.262584 | AG11: 59.817496 | AH11: 100 | AI11: 89.923551 | AJ11: 100 | AK11: 49.9512 | AL11: 98.808758 | AM11: 100 | AN11: 100 | AO11: 43.837117 | AP11: 100 | AQ11: 19.597851 | AR11: 100 | AS11: 15.355912 | AT11: 98.351048 | AU11: 93.886463 | AV11: 23.61385 | AW11: 0
B12: 3 | C12: 1 | D12: GUATEMALA | E12: 103 | F12: San José Pinula | G12: 0 | H12: 85.922171 | I12: 33.792444 | J12: 50 | K12: 41.282808 | L12: 100 | M12: 53.26557 | N12: 91.903368 | O12: 73.575408 | P12: 99.89 | Q12: 82.910037 | R12: 85.619938 | S12: 74.772727 | T12: 70.48877 | U12: 56.692385 | V12: 99.948009 | W12: 61.102564 | X12: 2.8146884 | Y12: 100 | Z12: 25.749598 | AA12: 100 | AB12: 70.78734 | AC12: 56.968591 | AD12: 19.929283 | AE12: 100 | AF12: 63.08669 | AG12: 36.578393 | AH12: 100 | AI12: 89.923551 | AJ12: 100 | AK12: 49.9512 | AL12: 96.030072 | AM12: 100 | AN12: 100 | AO12: 100 | AP12: 100 | AQ12: 1.4138106 | AR12: 71.063679 | AS12: 15.355912 | AT12: 82.871566 | AU12: 93.886463 | AV12: 14.200687 | AW12: 0
B13: 4 | C13: 1 | D13: GUATEMALA | E13: 104 | F13: San José Del Golfo | G13: 12.40575 | H13: 77.012895 | I13: 100 | J13: 50 | K13: 19.609533 | L13: 100 | M13: 53.26557 | N13: 93.698894 | O13: 76.933114 | P13: 100 | Q13: 68.504966 | R13: 98.10311 | S13: 52.97619 | T13: 61.820748 | U13: 56.692385 | V13: 88.877787 | W13: 63.948718 | X13: 17.670604 | Y13: 100 | Z13: 45.469882 | AA13: 100 | AB13: 75.428739 | AC13: 69.517816 | AD13: 5.1282051 | AE13: 100 | AF13: 100 | AG13: 23.947483 | AH13: 100 | AI13: 89.923551 | AJ13: 100 | AK13: 49.9512 | AL13: 83.688614 | AM13: 100 | AN13: 100 | AO13: 100 | AP13: 100 | AQ13: 0.35690126 | AR13: 0 | AS13: 15.355912 | AT13: 83.872998 | AU13: 93.886463 | AV13: 9.0844472 | AW13: 0
B14: 5 | C14: 1 | D14: GUATEMALA | E14: 105 | F14: Palencia | G14: 0 | H14: 82.473573 | I14: 66.748885 | J14: 50 | K14: 47.585135 | L14: 100 | M14: 53.26557 | N14: 91.331602 | O14: 74.836041 | P14: 97.59 | Q14: 65.892252 | R14: 72.449564 | S14: 9.6938776 | T14: 52.885985 | U14: 56.692385 | V14: 65.429255 | W14: 61.576923 | X14: 6.1320937 | Y14: 98.485002 | Z14: 35.370382 | AA14: 86.844216 | AB14: 44.34345 | AC14: 66.453422 | AD14: 5.2588997 | AE14: 100 | AF14: 94.924336 | AG14: 22.214573 | AH14: 100 | AI14: 89.923551 | AJ14: 100 | AK14: 49.9512 | AL14: 89.612469 | AM14: 100 | AN14: 100 | AO14: 100 | AP14: 100 | AQ14: 1.4044554 | AR14: 0 | AS14: 15.355912 | AT14: 84.191374 | AU14: 93.886463 | AV14: 8.3825198 | AW14: 0
B15: 6 | C15: 1 | D15: GUATEMALA | E15: 106 | F15: Chinautla | G15: 19.602788 | H15: 80.079376 | I15: 42.676127 | J15: 50 | K15: 48.122575 | L15: 100 | M15: 53.26557 | N15: 92.232817 | O15: 73.97855 | P15: 99.11 | Q15: 85.500588 | R15: 65.150468 | S15: 59.375 | T15: 80.112014 | U15: 56.692385 | V15: 100 | W15: 62.051282 | X15: 3.554479 | Y15: 100 | Z15: 30.833764 | AA15: 98.649898 | AB15: 47.365349 | AC15: 59.108895 | AD15: 6.8581781 | AE15: 100 | AF15: 71.232676 | AG15: 9.8014371 | AH15: 100 | AI15: 89.923551 | AJ15: 100 | AK15: 49.9512 | AL15: 98.830092 | AM15: 100 | AN15: 100 | AO15: 100 | AP15: 100 | AQ15: 3.5094517 | AR15: 98.250551 | AS15: 15.355912 | AT15: 70.716024 | AU15: 93.886463 | AV15: 3.3544914 | AW15: 0
B16: 7 | C16: 1 | D16: GUATEMALA | E16: 107 | F16: San Pedro Ayampuc | G16: 0 | H16: 66.902045 | I16: 44.077694 | J16: 50 | K16: 30.745217 | L16: 100 | M16: 53.26557 | N16: 90.944122 | O16: 72.893675 | P16: 98.7 | Q16: 78.808158 | R16: 5.9405894 | S16: 67.123288 | T16: 50.11747 | U16: 56.692385 | V16: 88.28022 | W16: 61.576923 | X16: 3.1022803 | Y16: 100 | Z16: 33.002151 | AA16: 79.089629 | AB16: 28.32436 | AC16: 66.012173 | AD16: 1.5873016 | AE16: 100 | AF16: 84.509881 | AG16: 5.7561193 | AH16: 100 | AI16: 89.923551 | AJ16: 100 | AK16: 49.9512 | AL16: 95.398097 | AM16: 100 | AN16: 100 | AO16: 100 | AP16: 100 | AQ16: 2.3850273 | AR16: 39.817608 | AS16: 15.355912 | AT16: 74.64774 | AU16: 93.886463 | AV16: 1.7159068 | AW16: 0
B17: 8 | C17: 1 | D17: GUATEMALA | E17: 108 | F17: Mixco | G17: 0 | H17: 83.772744 | I17: 82.734864 | J17: 50 | K17: 50.416795 | L17: 100 | M17: 53.26557 | N17: 92.778773 | O17: 73.984397 | P17: 99.83 | Q17: 94.724318 | R17: 83.01389 | S17: 91.287879 | T17: 100 | U17: 56.692385 | V17: 100 | W17: 56.358974 | X17: 2.1451103 | Y17: 100 | Z17: 18.76409 | AA17: 100 | AB17: 99.438662 | AC17: 55.270084 | AD17: 27.705346 | AE17: 100 | AF17: 45.94636 | AG17: 65.595642 | AH17: 100 | AI17: 89.923551 | AJ17: 100 | AK17: 49.9512 | AL17: 98.219447 | AM17: 100 | AN17: 100 | AO17: 79.008485 | AP17: 100 | AQ17: 30.161627 | AR17: 100 | AS17: 15.355912 | AT17: 94.884914 | AU17: 93.886463 | AV17: 25.954329 | AW17: 0
B18: 9 | C18: 1 | D18: GUATEMALA | E18: 109 | F18: San Pedro Sacatepéquez | G18: 73.149472 | H18: 100 | I18: 72.370791 | J18: 50 | K18: 26.423341 | L18: 100 | M18: 53.26557 | N18: 90.307419 | O18: 71.765279 | P18: 100 | Q18: 75.024907 | R18: 74.692011 | S18: 100 | T18: 52.825913 | U18: 56.692385 | V18: 71.764141 | W18: 71.064103 | X18: 2.229814 | Y18: 91.039899 | Z18: 34.624912 | AA18: 94.478054 | AB18: 2.9651046 | AC18: 55.915423 | AD18: 12.858556 | AE18: 100 | AF18: 83.828096 | AG18: 11.99773 | AH18: 100 | AI18: 89.923551 | AJ18: 100 | AK18: 49.9512 | AL18: 93.345607 | AM18: 100 | AN18: 100 | AO18: 100 | AP18: 100 | AQ18: 6.8016696 | AR18: 70.730637 | AS18: 15.355912 | AT18: 91.568327 | AU18: 93.886463 | AV18: 4.2441154 | AW18: 0
B19: 10 | C19: 1 | D19: GUATEMALA | E19: 110 | F19: San Juan Sacatepéquez | G19: 59.397097 | H19: 99.306371 | I19: 91.668287 | J19: 50 | K19: 43.962198 | L19: 100 | M19: 53.26557 | N19: 89.179832 | O19: 70.75425 | P19: 99.7 | Q19: 60.378501 | R19: 58.481435 | S19: 44.008264 | T19: 36.421965 | U19: 56.692385 | V19: 65.217363 | W19: 62.525641 | X19: 1.5085462 | Y19: 78.460243 | Z19: 33.548859 | AA19: 81.103043 | AB19: 33.581805 | AC19: 65.446863 | AD19: 5.1789077 | AE19: 100 | AF19: 52.188607 | AG19: 9.7377928 | AH19: 100 | AI19: 89.923551 | AJ19: 100 | AK19: 49.9512 | AL19: 94.934579 | AM19: 100 | AN19: 100 | AO19: 100 | AP19: 100 | AQ19: 4.6726307 | AR19: 64.735515 | AS19: 15.355912 | AT19: 85.481968 | AU19: 93.886463 | AV19: 3.3287118 | AW19: 0
B20: 11 | C20: 1 | D20: GUATEMALA | E20: 111 | F20: San Raymundo | G20: 78.295423 | H20: 100 | I20: 97.447459 | J20: 50 | K20: 22.534938 | L20: 100 | M20: 53.26557 | N20: 87.213829 | O20: 69.436645 | P20: 99.71 | Q20: 72.024062 | R20: 71.747733 | S20: 25.438596 | T20: 34.724464 | U20: 56.692385 | V20: 57.547061 | W20: 58.25641 | X20: 6.1972693 | Y20: 94.248995 | Z20: 42.572386 | AA20: 97.74091 | AB20: 59.876889 | AC20: 64.890691 | AD20: 3.3407572 | AE20: 100 | AF20: 94.533814 | AG20: 12.437816 | AH20: 100 | AI20: 89.923551 | AJ20: 100 | AK20: 49.9512 | AL20: 90.149215 | AM20: 100 | AN20: 100 | AO20: 100 | AP20: 100 | AQ20: 1.4824677 | AR20: 20.780522 | AS20: 15.355912 | AT20: 87.406389 | AU20: 93.886463 | AV20: 4.4223754 | AW20: 0
B21: 12 | C21: 1 | D21: GUATEMALA | E21: 112 | F21: Chuarrancho | G21: 86.951214 | H21: 100 | I21: 62.143617 | J21: 50 | K21: 21.744714 | L21: 100 | M21: 53.26557 | N21: 85.458087 | O21: 68.807039 | P21: 98.22 | Q21: 81.797411 | R21: 59.057948 | S21: 12.755102 | T21: 23.705422 | U21: 56.692385 | V21: 58.424915 | W21: 72.012821 | X21: 5.9524196 | Y21: 95.660998 | Z21: 26.881185 | AA21: 64.770459 | AB21: 0 | AC21: 82.030473 | AD21: 0 | AE21: 100 | AF21: 100 | AG21: 10.676452 | AH21: 100 | AI21: 89.923551 | AJ21: 100 | AK21: 49.9512 | AL21: 92.46284 | AM21: 100 | AN21: 100 | AO21: 100 | AP21: 100 | AQ21: 0.57122191 | AR21: 19.414593 | AS21: 15.355912 | AT21: 81.770097 | AU21: 93.886463 | AV21: 3.7089222 | AW21: 0
... B101: 92 | C101: 7 | D101: SOLOLA | E101: 707 | F101: Santa Clara La Laguna | G101: 95.356037 | H101: 100 | I101: 48.366013 | J101: 8.3333333 | K101: 35.73174 | L101: 100 | M101: 89.624241 | N101: 44.983149 | O101: 41.051059 | P101: 99.46 | Q101: 88.991477 | R101: 65.4949 | S101: 29.166667 | T101: 40.752941 | U101: 53.872414 | V101: 62.988195 | W101: 63.333333 | X101: 8.0046716 | Y101: 45.946662 | Z101: 60.064652 | AA101: 83.319577 | AB101: 68.537641 | AC101: 13.521608 | AD101: 0 | AE101: 11.640814 | AF101: 100 | AG101: 13.455674 | AH101: 100 | AI101: 47.792823 | AJ101: 16.886511 | AK101: 5.5944847 | AL101: 91.138599 | AM101: 82.357724 | AN101: 100 | AO101: 91.595142 | AP101: 82.109203 | AQ101: 1.2247823 | AR101: 0 | AS101: 36.549093 | AT101: 49.732274 | AU101: 93.886463 | AV101: 7.5134055 | AW101: 0
B102: 93 | C102: 7 | D102: SOLOLA | E102: 708 | F102: Concepción | G102: 100 | H102: 100 | I102: 99.1701 | J102: 8.3333333 | K102: 45.139134 | L102: 100 | M102: 89.624241 | N102: 50.889214 | O102: 45.5527 | P102: 98.68 | Q102: 68.321014 | R102: 56.341777 | S102: 5 | T102: 10.612574 | U102: 53.872414 | V102: 47.13937 | W102: 85.333333 | X102: 20.256632 | Y102: 24.415091 | Z102: 37.177633 | AA102: 83.433158 | AB102: 12.384521 | AC102: 14.384085 | AE102: 5.7540622 | AF102: 100 | AG102: 16.618222 | AH102: 100 | AI102: 47.792823 | AJ102: 16.886511 | AK102: 5.5944847 | AL102: 86.791873 | AM102: 82.357724 | AN102: 100 | AO102: 32.633056 | AP102: 40.586634 | AQ102: 0.51431052 | AR102: 15.689892 | AS102: 36.549093 | AT102: 77.749364 | AU102: 93.886463 | AV102: 9.4240145 | AW102: 0
B103: 94 | C103: 7 | D103: SOLOLA | E103: 709 | F103: San Andrés Semetabaj | G103: 100 | H103: 100 | I103: 53.055537 | J103: 8.3333333 | K103: 47.360971 | L103: 100 | M103: 89.624241 | N103: 63.089316 | O103: 54.858629 | P103: 99.98 | Q103: 69.01435 | R103: 72.616533 | S103: 14.583333 | T103: 39.4357 | U103: 53.872414 | V103: 74.754544 | W103: 67 | X103: 6.5396445 | Y103: 46.584635 | Z103: 44.762113 | AA103: 81.644019 | AB103: 85.312547 | AC103: 12.772001 | AD103: 16.260163 | AE103: 5.2869314 | AF103: 91.836433 | AG103: 14.559091 | AH103: 100 | AI103: 47.792823 | AJ103: 16.886511 | AK103: 5.5944847 | AL103: 94.378534 | AM103: 82.357724 | AN103: 100 | AO103: 27.954244 | AP103: 37.291698 | AQ103: 0.96919066 | AR103: 81.595003 | AS103: 36.549093 | AT103: 79.972601 | AU103: 93.886463 | AV103: 8.1800193 | AW103: 0
B104: 95 | C104: 7 | D104: SOLOLA | E104: 710 | F104: Panajachel | G104: 73.631702 | H104: 100 | I104: 0 | J104: 8.3333333 | K104: 48.061282 | L104: 100 | M104: 89.624241 | N104: 50.436469 | O104: 45.207615 | P104: 100 | Q104: 94.686907 | R104: 87.640283 | S104: 100 | T104: 83.093936 | U104: 53.872414 | V104: 100 | W104: 41.333333 | X104: 20.559275 | Y104: 92.518654 | Z104: 40.276085 | AA104: 100 | AB104: 98.306054 | AC104: 10.528719 | AD104: 5.2434457 | AE104: 4.7601051 | AF104: 96.300967 | AG104: 46.288848 | AH104: 100 | AI104: 47.792823 | AJ104: 16.886511 | AK104: 5.5944847 | AL104: 96.167672 | AM104: 82.357724 | AN104: 100 | AO104: 22.677518 | AP104: 33.575696 | AQ104: 2.570767 | AR104: 98.029426 | AS104: 36.549093 | AT104: 82.47995 | AU104: 93.886463 | AV104: 27.349104 | AW104: 0
B105: 96 | C105: 7 | D105: SOLOLA | E105: 711 | F105: Santa Catarina Palopó | G105: 73.480803 | H105: 100 | I105: 66.38039 | J105: 8.3333333 | K105: 26.55564 | L105: 100 | M105: 89.624241 | N105: 60.711338 | O105: 52.330513 | P105: 94.32 | Q105: 71.794872 | R105: 68.30797 | S105: 31.25 | T105: 17.028986 | U105: 53.872414 | V105: 54.636663 | W105: 75.555556 | X105: 6.0892112 | Y105: 56.632701 | Z105: 47.937091 | AA105: 86.775218 | AB105: 38.883445 | AC105: 14.003345 | AE105: 10.607359 | AF105: 100 | AG105: 15.400461 | AH105: 100 | AI105: 47.792823 | AJ105: 16.886511 | AK105: 5.5944847 | AL105: 93.479392 | AM105: 82.357724 | AN105: 100 | AO105: 81.243988 | AP105: 74.819663 | AQ105: 0.94011372 | AR105: 24.353991 | AS105: 36.549093 | AT105: 54.650845 | AU105: 93.886463 | AV105: 8.6883214 | AW105: 0
B106: 97 | C106: 7 | D106: SOLOLA | E106: 712 | F106: San Antonio Palopó | G106: 100 | H106: 100 | I106: 97.204839 | J106: 8.3333333 | K106: 30.43683 | L106: 100 | M106: 89.624241 | N106: 64.835194 | O106: 54.660399 | P106: 97.01 | Q106: 66.080171 | R106: 68.345633 | S106: 30.882353 | T106: 25.05632 | U106: 53.872414 | V106: 41.579591 | W106: 66.388889 | X106: 4.8963085 | Y106: 45.787169 | Z106: 44.956471 | AA106: 66.906283 | AB106: 52.288218 | AC106: 16.885669 | AD106: 0 | AE106: 7.8672811 | AF106: 96.147117 | AG106: 13.417605 | AH106: 100 | AI106: 47.792823 | AJ106: 16.886511 | AK106: 5.5944847 | AL106: 91.162572 | AM106: 82.357724 | AN106: 100 | AO106: 53.799193 | AP106: 55.492354 | AQ106: 0.95956331 | AR106: 24.436386 | AS106: 36.549093 | AT106: 67.691824 | AU106: 93.886463 | AV106: 7.4904066 | AW106: 0
B107: 98 | C107: 7 | D107: SOLOLA | E107: 713 | F107: San Lucas Tolimán | G107: 93.842436 | H107: 97.818509 | I107: 67.023501 | J107: 8.3333333 | K107: 35.157277 | L107: 100 | M107: 89.624241 | N107: 60.043072 | O107: 53.333356 | P107: 97.88 | Q107: 66.135583 | R107: 72.309653 | S107: 11.637931 | T107: 29.504944 | U107: 53.872414 | V107: 55.16134 | W107: 46.833333 | X107: 20.82273 | Y107: 54.240305 | Z107: 39.14637 | AA107: 99.842594 | AB107: 49.421303 | AC107: 13.087919 | AD107: 7.3839662 | AE107: 8.6994655 | AF107: 79.337138 | AG107: 15.311519 | AH107: 100 | AI107: 47.792823 | AJ107: 16.886511 | AK107: 5.5944847 | AL107: 89.418889 | AM107: 82.357724 | AN107: 100 | AO107: 62.134405 | AP107: 61.362218 | AQ107: 0.50820862 | AR107: 0 | AS107: 36.549093 | AT107: 63.731171 | AU107: 93.886463 | AV107: 8.6345884 | AW107: 0
B108: 99 | C108: 7 | D108: SOLOLA | E108: 714 | F108: Santa Cruz La Laguna | G108: 100 | H108: 100 | I108: 89.021427 | J108: 8.3333333 | K108: 31.957587 | L108: 100 | M108: 89.624241 | N108: 48.79712 | O108: 43.958092 | P108: 95.67 | Q108: 72.098022 | R108: 43.863241 | S108: 45.833333 | T108: 28.205765 | U108: 53.872414 | V108: 40.912935 | W108: 79.222222 | X108: 15.875501 | Y108: 26.010022 | Z108: 40.364483 | AA108: 76.486225 | AB108: 55.43477 | AC108: 16.161598 | AE108: 11.627782 | AF108: 100 | AG108: 18.895963 | AH108: 100 | AI108: 47.792823 | AJ108: 16.886511 | AK108: 5.5944847 | AL108: 92.371618 | AM108: 82.357724 | AN108: 100 | AO108: 91.464612 | AP108: 82.017281 | AQ108: 0.92603545 | AR108: 0 | AS108: 36.549093 | AT108: 49.794298 | AU108: 93.886463 | AV108: 10.80008 | AW108: 0
B109: 100 | C109: 7 | D109: SOLOLA | E109: 715 | F109: San Pablo La Laguna | G109: 100 | H109: 100 | I109: 39.991247 | J109: 8.3333333 | K109: 22.122191 | L109: 100 | M109: 89.624241 | N109: 42.922948 | O109: 39.480761 | P109: 96.36 | Q109: 60.144509 | R109: 68.600219 | S109: 29.166667 | T109: 19.10389 | U109: 53.872414 | V109: 42.820156 | W109: 78 | X109: 15.435673 | Y109: 32.708733 | Z109: 71.606597 | AA109: 87.85545 | AB109: 62.639027 | AC109: 13.07588 | AD109: 0 | AE109: 22.090206 | AF109: 100 | AG109: 8.6311097 | AH109: 100 | AI109: 47.792823 | AJ109: 16.886511 | AK109: 5.5944847 | AL109: 91.537567 | AM109: 82.357724 | AN109: 100 | AO109: 100 | AP109: 100 | AQ109: 0.48676039 | AR109: 0 | AS109: 36.549093 | AT109: 0 | AU109: 93.886463 | AV109: 4.5987131 | AW109: 0
B110: 101 | C110: 7 | D110: SOLOLA | E110: 716 | F110: San Marcos La Laguna | G110: 100 | H110: 100 | I110: 0 | J110: 8.3333333 | K110: 49.407335 | L110: 100 | M110: 89.624241 | N110: 42.220651 | O110: 38.945466 | P110: 99.89 | Q110: 93.486239 | R110: 59.664676 | S110: 12.5 | T110: 64.563268 | U110: 53.872414 | V110: 62.688834 | W110: 78.611111 | X110: 14.323413 | Y110: 46.106155 | Z110: 43.686625 | AA110: 100 | AB110: 80.156682 | AC110: 10.953147 | AE110: 4.5952852 | AF110: 100 | AG110: 11.593872 | AH110: 100 | AI110: 47.792823 | AJ110: 16.886511 | AK110: 5.5944847 | AL110: 96.482432 | AM110: 82.357724 | AN110: 100 | AO110: 21.026671 | AP110: 32.413128 | AQ110: 0.87606594 | AR110: 100 | AS110: 36.549093 | AT110: 83.264385 | AU110: 93.886463 | AV110: 6.3886239 | AW110: 0
B111: 102 | C111: 7 | D111: SOLOLA | E111: 717 | F111: San Juan La Laguna | G111: 82.663181 | H111: 100 | I111: 0 | J111: 8.3333333 | K111: 20.260914 | L111: 100 | M111: 89.624241 | N111: 41.579839 | O111: 40.850407 | P111: 99.13 | Q111: 75.3703 | R111: 73.17424 | S111: 12.5 | T111: 48.407643 | U111: 53.872414 | V111: 60.310642 | W111: 68.833333 | X111: 11.307345 | Y111: 37.493527 | Z111: 53.5905 | AA111: 89.594072 | AB111: 83.448034 | AC111: 11.602488 | AD111: 2.3474178 | AE111: 12.268463 | AF111: 100 | AG111: 10.291704 | AH111: 100 | AI111: 47.792823 | AJ111: 16.886511 | AK111: 5.5944847 | AL111: 94.352879 | AM111: 82.357724 | AN111: 100 | AO111: 97.881711 | AP111: 86.536361 | AQ111: 0.5028497 | AR111: 23.830048 | AS111: 36.549093 | AT111: 46.745077 | AU111: 93.886463 | AV111: 5.601938 | AW111: 0
B112: 103 | C112: 7 | D112: SOLOLA | E112: 718 | F112: San Pedro La Laguna | G112: 96.702394 | H112: 100 | I112: 24.362033 | J112: 8.3333333 | K112: 46.492451 | L112: 100 | M112: 89.624241 | N112: 40.630949 | O112: 40.512172 | P112: 99.38 | Q112: 91.318389 | R112: 89.277987 | S112: 25 | T112: 57.530904 | U112: 53.872414 | V112: 97.892269 | W112: 46.833333 | X112: 13.481371 | Y112: 93.475613 | Z112: 33.211474 | AA112: 100 | AB112: 84.463862 | AC112: 12.026067 | AD112: 14.124294 | AE112: 8.4561144 | AF112: 100 | AG112: 13.161372 | AH112: 100 | AI112: 47.792823 | AJ112: 16.886511 | AK112: 5.5944847 | AL112: 90.566119 | AM112: 82.357724 | AN112: 100 | AO112: 59.696985 | AP112: 59.645726 | AQ112: 0.97331521 | AR112: 9.7382138 | AS112: 36.549093 | AT112: 64.889363 | AU112: 93.886463 | AV112: 7.3356073 | AW112: 0
B113: 104 | C113: 7 | D113: SOLOLA | E113: 719 | F113: Santiago Atitlán | G113: 98.480884 | H113: 100 | I113: 80.565757 | J113: 8.3333333 | K113: 32.447965 | L113: 100 | M113: 89.624241 | N113: 55.273636 | O113: 49.698061 | P113: 98.24 | Q113: 75.069486 | R113: 82.59205 | S113: 8.4558824 | T113: 27.284637 | U113: 53.872414 | V113: 59.890097 | W113: 52.944444 | X113: 10.922017 | Y113: 61.895975 | Z113: 39.797455 | AA113: 87.679938 | AB113: 71.379777 | AC113: 9.9438308 | AD113: 15.258216 | AE113: 12.795772 | AF113: 62.86051 | AG113: 9.4860566 | AH113: 100 | AI113: 47.792823 | AJ113: 16.886511 | AK113: 5.5944847 | AL113: 96.59247 | AM113: 82.357724 | AN113: 100 | AO113: 100 | AP113: 90.255768 | AQ113: 0.42352296 | AR113: 60.228334 | AS113: 36.549093 | AT113: 44.235432 | AU113: 93.886463 | AV113: 5.1152172 | AW113: 0
B114: 105 | C114: 8 | D114: TOTONICAPAN | E114: 801 | F114: Totonicapán | G114: 84.093879 | H114: 100 | I114: 100 | J114: 41.666667 | K114: 48.817119 | L114: 100 | M114: 74.679342 | N114: 39.392066 | O114: 36.789583 | P114: 98.57 | Q114: 52.580927 | R114: 50.82775 | S114: 17.22561 | T114: 46.712908 | U114: 53.872414 | V114: 68.014022 | W114: 85.230769 | X114: 47.244827 | Y114: 46.920918 | Z114: 66.633236 | AA114: 82.433759 | AB114: 77.979056 | AC114: 11.702734 | AD114: 8.0240722 | AE114: 6.5743005 | AF114: 27.617994 | AG114: 22.237275 | AH114: 100 | AI114: 43.193793 | AJ114: 0.88593861 | AK114: 0 | AL114: 81.405778 | AM114: 73.082437 | AN114: 100 | AO114: 22.153441 | AP114: 26.951066 | AQ114: 1.0656647 | AR114: 43.537766 | AS114: 0 | AT114: 78.460673 | AU114: 93.886463 | AV114: 13.052087 | AW114: 0
B115: 106 | C115: 8 | D115: TOTONICAPAN | E115: 802 | F115: San Cristóbal Totonicapán | G115: 92.127355 | H115: 100 | I115: 100 | J115: 41.666667 | K115: 32.874636 | L115: 100 | M115: 74.679342 | N115: 36.373112 | O115: 34.488433 | P115: 97.3 | Q115: 45.59199 | R115: 49.412636 | S115: 50 | T115: 28.697191 | U115: 53.872414 | V115: 68.807954 | W115: 82.769231 | X115: 27.377435 | Y115: 50.810415 | Z115: 38.013234 | AA115: 75.904854 | AB115: 81.744712 | AC115: 13.042811 | AD115: 12.717537 | AE115: 5.2365977 | AF115: 99.998854 | AG115: 13.270023 | AH115: 100 | AI115: 43.193793 | AJ115: 0.88593861 | AK115: 0 | AL115: 88.953188 | AM115: 73.082437 | AN115: 100 | AO115: 12.558916 | AP115: 21.46721 | AQ115: 4.4453986 | AR115: 86.236495 | AS115: 0 | AT115: 83.888206 | AU115: 93.886463 | AV115: 7.5405287 | AW115: 0
B116: 107 | C116: 8 | D116: TOTONICAPAN | E116: 803 | F116: San Francisco El Alto | G116: 100 | H116: 100 | I116: 100 | J116: 41.666667 | K116: 40.2526 | L116: 66.666667 | M116: 74.679342 | N116: 68.971379 | O116: 33.462952 | P116: 97.12 | Q116: 48.317173 | R116: 57.014223 | S116: 13.257576 | T116: 24.431835 | U116: 53.872414 | V116: 76.474634 | W116: 83.589744 | X116: 6.2601586 | Y116: 44.471975 | Z116: 40.050752 | AA116: 72.925482 | AB116: 19.976054 | AC116: 14.75232 | AD116: 0 | AE116: 6.9363571 | AF116: 61.55449 | AG116: 8.6834276 | AH116: 100 | AI116: 43.193793 | AJ116: 0.88593861 | AK116: 0 | AL116: 94.141942 | AM116: 73.082437 | AN116: 100 | AO116: 24.750252 | AP116: 28.435302 | AQ116: 1.4050028 | AR116: 97.44306 | AS116: 1.4394102e-16 | AT116: 76.991681 | AU116: 93.886463 | AV116: 4.7214611 | AW116: 0
B117: 108 | C117: 8 | D117: TOTONICAPAN | E117: 804 | F117: San Andrés Xecul | G117: 100 | H117: 100 | I117: 99.575714 | J117: 41.666667 | K117: 29.782641 | L117: 100 | M117: 74.679342 | N117: 35.107597 | O117: 33.52385 | P117: 98.37 | Q117: 50.930188 | R117: 48.231071 | S117: 29.411765 | T117: 28.30354 | U117: 53.872414 | V117: 61.899196 | W117: 57.333333 | X117: 7.9617112 | Y117: 41.590866 | Z117: 43.894926 | AA117: 69.630697 | AB117: 28.042662 | AC117: 14.335155 | AD117: 100 | AE117: 10.315149 | AF117: 100 | AG117: 7.7531575 | AH117: 100 | AI117: 43.193793 | AJ117: 0.88593861 | AK117: 0 | AL117: 90.113901 | AM117: 73.082437 | AN117: 100 | AO117: 48.984263 | AP117: 42.286517 | AQ117: 3.339385 | AR117: 56.556629 | AS117: 0 | AT117: 63.282725 | AU117: 93.886463 | AV117: 4.1496874 | AW117: 0
B118: 109 | C118: 8 | D118: TOTONICAPAN | E118: 805 | F118: Momostenango | G118: 99.084889 | H118: 100 | I118: 59.245961 | J118: 41.666667 | K118: 26.534971 | L118: 100 | M118: 74.679342 | N118: 68.914334 | O118: 29.776284 | P118: 95.52 | Q118: 40.059636 | R118: 32.103334 | S118: 15.081967 | T118: 15.825162 | U118: 53.872414 | V118: 53.862517 | W118: 54.051282 | X118: 4.3612716 | Y118: 34.099983 | Z118: 36.878699 | AA118: 61.789758 | AB118: 29.039571 | AC118: 15.901446 | AD118: 1.8315018 | AE118: 12.883367 | AF118: 54.12443 | AG118: 7.7620581 | AH118: 100 | AI118: 43.193793 | AJ118: 0.88593861 | AK118: 0 | AL118: 88.146934 | AM118: 73.082437 | AN118: 100 | AO118: 67.404518 | AP118: 52.814816 | AQ118: 0.69127374 | AR118: 22.766243 | AS118: 1.4394102e-16 | AT118: 52.862557 | AU118: 93.886463 | AV118: 4.155158 | AW118: 0
B119: 110 | C119: 8 | D119: TOTONICAPAN | E119: 806 | F119: Santa María Chiquimula | G119: 100 | H119: 100 | I119: 100 | J119: 41.666667 | K119: 29.490478 | L119: 100 | M119: 74.679342 | N119: 68.349143 | O119: 27.982194 | P119: 88.03 | Q119: 46.50442 | R119: 43.452097 | S119: 23.75 | T119: 12.71401 | U119: 53.872414 | V119: 34.806511 | W119: 77.025641 | X119: 5.661774 | Y119: 32.083206 | Z119: 39.873945 | AA119: 66.843281 | AB119: 20.412177 | AC119: 13.312354 | AD119: 5.3763441 | AE119: 10.835519 | AF119: 57.723531 | AG119: 5.9824815 | AH119: 100 | AI119: 43.193793 | AJ119: 0.88593861 | AK119: 0 | AL119: 90.454838 | AM119: 73.082437 | AN119: 100 | AO119: 52.716557 | AP119: 44.419751 | AQ119: 1.3001404 | AR119: 55.545619 | AS119: 1.4394102e-16 | AT119: 61.171401 | AU119: 93.886463 | AV119: 3.0613736 | AW119: 0
B120: 111 | C120: 8 | D120: TOTONICAPAN | E120: 807 | F120: Santa Lucía La Reforma | G120: 100 | H120: 100 | I120: 100 | J120: 41.666667 | K120: 38.162924 | L120: 100 | M120: 74.679342 | N120: 77.615447 | O120: 36.157053 | P120: 90.82 | Q120: 32.500785 | R120: 35.163541 | S120: 1.8382353 | T120: 12.011666 | U120: 53.872414 | V120: 26.771341 | W120: 56.512821 | X120: 8.1880516 | Y120: 43.175476 | Z120: 29.450298 | AA120: 67.757456 | AB120: 36.178235 | AC120: 17.577355 | AE120: 11.579405 | AF120: 96.263899 | AG120: 7.579771 | AH120: 100 | AI120: 43.193793 | AJ120: 0.88593861 | AK120: 0 | AL120: 97.18398 | AM120: 73.082437 | AN120: 100 | AO120: 58.052001 | AP120: 47.469282 | AQ120: 0.30414464 | AR120: 100 | AS120: 0 | AT120: 58.15319 | AU120: 93.886463 | AV120: 4.0431186 | AW120: 0
B121: 112 | C121: 8 | D121: TOTONICAPAN | E121: 808 | F121: San Bartolo Aguas Calientes | G121: 100 | H121: 100 | I121: 68.930367 | J121: 41.666667 | K121: 28.363304 | L121: 100 | M121: 74.679342 | N121: 65.002384 | O121: 27.041167 | P121: 93.14 | Q121: 52.300613 | R121: 37.326313 | S121: 24.074074 | T121: 19.566593 | U121: 53.872414 | V121: 47.344816 | W121: 49.948718 | X121: 13.814554 | Y121: 44.904141 | Z121: 62.309967 | AA121: 76.245167 | AB121: 48.638444 | AC121: 16.551743 | AE121: 9.2645138 | AF121: 99.448885 | AG121: 15.469323 | AH121: 100 | AI121: 43.193793 | AJ121: 0.88593861 | AK121: 0 | AL121: 74.806744 | AM121: 73.082437 | AN121: 100 | AO121: 41.448697 | AP121: 37.979482 | AQ121: 0.95227923 | AR121: 0 | AS121: 1.4394102e-16 | AT121: 67.545525 | AU121: 93.886463 | AV121: 8.8922882 | AW121: 0
B122: 113 | C122: 9 | D122: QUETZALTENANGO | E122: 901 | F122: Quetzaltenango | G122: 54.816745 | H122: 100 | I122: 75.147973 | J122: 0 | K122: 59.484984 | L122: 66.666667 | M122: 65.257159 | N122: 32.157359 | O122: 31.27516 | P122: 98.8 | Q122: 90.485906 | R122: 95.840397 | S122: 100 | T122: 86.783547 | U122: 53.872414 | V122: 100 | W122: 72.823529 | X122: 71.284046 | Y122: 90.887819 | Z122: 69.09631 | AA122: 100 | AB122: 98.760401 | AC122: 22.954059 | AD122: 18.292289 | AE122: 9.6707234 | AF122: 23.593542 | AG122: 94.932715 | AH122: 100 | AI122: 78.50604 | AJ122: 38.241855 | AK122: 19.279766 | AL122: 86.384779 | AM122: 97.729767 | AN122: 100 | AO122: 13.907349 | AP122: 24.299108 | AQ122: 11.502959 | AR122: 92.840101 | AS122: 3.9844213 | AT122: 93.513062 | AU122: 93.886463 | AV122: 40.127557 | AW122: 0
...

Sheet ICL 2024 (datos serie original)
D2: ÍNDICE DE COMPETITIVIDAD LOCAL
D4: Fundación para el Desarrollo de Guatemala - FUNDESA -
F5: Fuente: | G5: PNC | H5: PNC | I5: OJ | J5: COPADEH | K5: SEGEPLAN | L5: SEGEPLAN | M5: DGC | N5: SEGEPLAN | O5: SEGEPLAN | P5: MEM | Q5: INE | R5: INE | S5: SIT | T5: INE | U5: INE | V5: INE | W5: INE | X5: MINFIN | Y5: MSPAS | Z5: MINFIN | AA5: MINEDUC | AB5: MINEDUC | AC5: INTECAP | AD5: MINEDUC | AE5: SAT | AF5: MINFIN | AG5: IGSS | AH5: IGSS | AI5: IGSS | AJ5: INE | AK5: INE / IGSS | AL5: IGM | AM5: SIB | AN5: SIB | AO5: SIB | AP5: SIB | AQ5: FUNDESA | AR5: BANGUAT | AS5: INGUAT | AT5: Doing Business | AU5: Doing Business | AV5: IGSS | AW5: MINFIN
F6: Año: | G6: 2023 | H6: 2023 | I6: 2023 | J6: 2023 | K6: 2021 | L6: 2023 | M6: 2023 | N6: 2023 | O6: 2023 | P6: 2023 | Q6: 2018 | R6: 2018 | S6: 2023 | T6: 2019 | U6: 2023 | V6: 2023 | W6: 2023 | X6: 2023 | Y6: 2015 | Z6: 2023 | AA6: 2023 | AB6: 2023 | AC6: 2023 | AD6: 2023 | AE6: 2023 | AF6: 2023 | AG6: 2023 | AH6: 2023 | AI6: 2023 | AJ6: 2023 | AK6: 2023 | AL6: 2023 | AM6: 2023 | AN6: 2023 | AO6: 2023 | AP6: 2023 | AQ6: 2023 | AR6: 2023 | AS6: 2023 | AT6: 2019 | AU6: 2019 | AV6: 2023 | AW6: 2023
F7: Desagregación: | G7: municipal | H7: municipal | I7: municipal | J7: departamental | K7: municipal | L7: municipal | M7: municipal | N7: municipal | O7: municipal | P7: municipal | Q7: municipal | R7: municipal | S7: municipal | T7: municipal | U7: regional | V7: municipal | W7: municipal | X7: municipal | Y7: municipal | Z7: municipal | AA7: municipal | AB7: municipal | AC7: municipal | AD7: municipal | AE7: departamental | AF7: municipal | AG7: municipal | AH7: departamental | AI7: departamental | AJ7: departamental | AK7: departamental | AL7: municipal | AM7: departamental | AN7: departamental | AO7: departamental | AP7: departamental | AQ7: municipal | AR7: municipal | AS7: departamental | AT7: nacional | AU7: nacional | AV7: municipal | AW7: municipal
G8: 1.1 | H8: 1.2 | I8: 1.3 | J8: 1.4 | K8: 1.5 | L8: 1.6 | M8: 2.1 | N8: 2.2 | O8: 2.3 | P8: 2.4 | Q8: 2.5 | R8: 2.6 | S8: 3.1 | T8: 3.2 | U8: 4.1 | V8: 4.2 | W8: 4.3 | X8: 5.1 | Y8: 5.2 | Z8: 6.1 | AA8: 6.2 | AB8: 6.3 | AC8: 6.4 | AD8: 6.5 | AE8: 7.1 | AF8: 7.2 | AG8: 8.1 | AH8: 8.2 | AI8: 8.3 | AJ8: 8.4 | AK8: 8.5 | AL8: 8.6 | AM8: 9.1 | AN8: 9.2 | AO8: 9.3 | AP8: 9.4 | AQ8: 10.1 | AR8: 10.2 | AS8: 10.3 | AT8: 11.1 | AU8: 11.2 | AV8: 11.3 | AW8: 12.1
